<?xml version="1.0" ?>
<robot name="JetBot"  xmlns:xacro="http://ros.org/wiki/xacro">

  <property name="M_PI_2" value="1.570796327"/>

  <joint name="left_wheel_hinge" type="continuous">
    <parent link="base_link"/>
    <child link="left_wheel"/>
    <origin rpy="0       0       1.57079" xyz="0.03     0.05125  0.03"/>
    <axis xyz="1  0  0"/>
  </joint>

  <transmission name="tran_jetbot_left_wheel_hinge">
    <type>transmission_interface/SimpleTransmission</type>
    <joint name="left_wheel_hinge">
      <hardwareInterface>hardware_interface/VelocityJointInterface</hardwareInterface>
    </joint>
    <actuator name="motor_left_wheel">
      <mechanicalReduction>1</mechanicalReduction>
      <hardwareInterface>VelocityJointInterface</hardwareInterface>
    </actuator>
  </transmission>

  <joint name="right_wheel_hinge" type="continuous">
    <parent link="base_link"/>
    <child link="right_wheel"/>
    <origin rpy="0       0       1.57079" xyz="0.03   -0.0595  0.03"/>
    <axis xyz="1  0  0"/>
  </joint>

  <transmission name="tran_jetbot_right_wheel_hinge">
    <type>transmission_interface/SimpleTransmission</type>
    <joint name="right_wheel_hinge">
      <hardwareInterface>hardware_interface/VelocityJointInterface</hardwareInterface>
    </joint>
    <actuator name="motor_right_wheel">
      <mechanicalReduction>1</mechanicalReduction>
    </actuator>
  </transmission>

  <joint name="camera_joint" type="fixed">
    <parent link="base_link"/>
    <child link="camera_link"/>
    <origin rpy="0    0.25  0" xyz="0.065   0      0.0857"/>
    <axis xyz="0.96891  0       0.2474"/>
  </joint>

  <joint name="imu_joint" type="fixed">
    <parent link="base_link"/>
    <child link="imu_link"/>
    <origin rpy="0 0 0" xyz="0   0      0.05"/>
  </joint>

  <joint name="laser_joint" type="fixed">
    <parent link="base_link"/>
    <child link="laser"/>
    <origin xyz="0.0 0 0.058" rpy="0 0 0"/>
  </joint>

  <link name="imu_link"/>
  <link name="laser"/>

  <link name="base_link">
    <inertial>
      <mass value="1.0"/>
      <origin rpy="0  0  0" xyz="0  0  0"/>
      <inertia ixx="1e-3" ixy="0" ixz="0" iyy="1e-3" iyz="0" izz="1e-3"/>
    </inertial>
    <collision name="collision">
      <origin rpy="0  0 0" xyz="0     0     0.043"/>
      <geometry>
        <!-- Replaced .dae mesh with a simple box -->
        <box size="0.13 0.11 0.05"/> 
      </geometry>
    </collision>
    <visual name="visual">
      <origin rpy="0  0 0" xyz="0     0     0.043"/>
      <geometry>
        <!-- Replaced .dae mesh with a simple box -->
        <box size="0.13 0.11 0.05"/>
      </geometry>
      <!-- Optional: Add a material color so it's easier to see in RViz -->
      <material name="green">
        <color rgba="0.0 0.8 0.0 1.0"/>
      </material>
    </visual>
  </link>

  <link name="left_wheel">
    <inertial>
      <mass value="0.1"/>
      <origin rpy="0  0  0" xyz="0  0  0"/>
      <inertia ixx="1e-3" ixy="0" ixz="0" iyy="1e-3" iyz="0" izz="1e-3"/>
    </inertial>
    <collision name="collision">
      <origin rpy="0  ${M_PI_2} 0" xyz="0 0 0"/>
      <geometry>
        <cylinder radius="0.030" length="0.008"/>
      </geometry>
    </collision>
    <visual name="visual">
      <origin rpy="0  ${M_PI_2} 0" xyz="0 0 0"/>
      <geometry>
        <!-- Replaced .stl mesh with standard cylinder -->
        <cylinder radius="0.030" length="0.008"/>
      </geometry>
      <!-- Added a dark gray/black material for RViz -->
      <material name="dark_gray">
        <color rgba="0.2 0.2 0.2 1.0"/>
      </material>
    </visual>
  </link>

  <link name="right_wheel">
    <inertial>
      <mass value="0.1"/>
      <origin rpy="0  0  0" xyz="0  0  0"/>
      <inertia ixx="1e-3" ixy="0" ixz="0" iyy="1e-3" iyz="0" izz="1e-3"/>
    </inertial>
    <collision name="collision">
      <origin rpy="0  ${M_PI_2} 0" xyz="0 0 0"/>
      <geometry>
        <cylinder radius="0.030" length="0.008"/>
      </geometry>
    </collision>
    <visual name="visual">
      <!-- Matched the collision origin so the cylinder stands up like a wheel -->
      <origin rpy="0  ${M_PI_2} 0" xyz="0 0 0"/>
      <geometry>
        <!-- Replaced .stl mesh with standard cylinder -->
        <cylinder radius="0.030" length="0.008"/>
      </geometry>
      <!-- Added a dark gray/black material for RViz -->
      <material name="dark_gray">
        <color rgba="0.2 0.2 0.2 1.0"/>
      </material>
    </visual>
  </link>

  <link name="camera_link">
    <inertial>
      <mass value="0.01"/>
      <origin rpy="0  0  0" xyz="0  0  0"/>
      <inertia ixx="0" ixy="0" ixz="0" iyy="0" iyz="0" izz="0"/>
    </inertial>
    <visual name="visual">
      <origin rpy="0  0  0" xyz="0  0  0"/>
      <geometry>
        <box size="0.001 0.001 0.001"/>
      </geometry>
    </visual>

  </link>

</robot>
